Workbook

Sheet Front
B2: THE METHODIST CHURCH GHANA
B3: ACCRA NORTH DIOCESE
B4: GA SUB-URBAN CIRCUIT
B5: HEBRON SOCIETY
B6: STATEMENT OF ACCOUNT FOR THE PERIOD 1ST JANUARY,2024 TO 31ST DECEMBER,2024
B11: DRAFT
B19: FINANCIAL STATEMENTS
B20: FOR THE PERIOD ENDING 31ST DECEMBER, 2024

Sheet Rec & Pmt
A1: =+Front!B2 -> THE METHODIST CHURCH GHANA
A2: =+Front!B3 -> ACCRA NORTH DIOCESE
A3: =+Front!B4 -> GA SUB-URBAN CIRCUIT
A4: =+Front!B5 -> HEBRON SOCIETY
A5: =+Front!B6 -> STATEMENT OF ACCOUNT FOR THE PERIOD 1ST JANUARY,2024 TO 31ST DECEMBER,2024
B7: 2024 | C7: 2023 | G7: 2022 | H7: 2021 | I7: TOTAL
B8: GHS | C8: GHS | G8: GHS | H8: GHS | I8: GHS
A10: BALANCE b/f
A11: GA RURAL BANK CURRENT | B11: =C75 -> 52205.88 | C11: 75100
A12: REPUBLIC BANK | B12: =C76 -> 200 | C12: 0
A13: CASH ON HAND | B13: =C77 -> 6557.7 | C13: 12166 | G13: 8030
B14: =+B12+B11+B13 -> 58963.58 | C14: 87266 | G14: 8030
A15: RECEIPTS
A16: OFFERING | B16: =+'RECEIPTS AND PAYMENT ANANLYSIS'!N8 -> 40490.5 | C16: 30724 | G16: 19146.6 | H16: 9074.3 | I16: =+B16+C16+H16+G16 -> 99435.4
A17: TITHE | B17: =+'RECEIPTS AND PAYMENT ANANLYSIS'!N9 -> 96711 | C17: 61571 | G17: 46708 | H17: 13965 | I17: =+B17+C17+H17+G17 -> 218955
A18: WEEKDAY ACTIVITY | B18: =+'RECEIPTS AND PAYMENT ANANLYSIS'!N10 -> 2772.1 | C18: 4168.7 | G18: 4350.9 | H18: 3617 | I18: =+B18+C18+H18+G18 -> 14908.7
A19: THANKS OFFERING | B19: =+'RECEIPTS AND PAYMENT ANANLYSIS'!N11 -> 4490 | C19: 6414 | G19: 1570 | H19: 140 | I19: =+B19+C19+H19+G19 -> 12614
A20: HARVEST | B20: =+'RECEIPTS AND PAYMENT ANANLYSIS'!N12 -> 238458.9 | C20: 150421 | G20: 55750.8 | H20: 24354.3 | I20: =+B20+C20+H20+G20 -> 468985
A21: WELFARE | B21: =+'RECEIPTS AND PAYMENT ANANLYSIS'!N13 -> 4704.5 | C21: 0 | G21: 0 | I21: =+B21+C21+H21+G21 -> 4704.5
A22: SPECIAL OFFERING | B22: =+'RECEIPTS AND PAYMENT ANANLYSIS'!N14 -> 893 | C22: 1296 | G22: 9245 | H22: 240 | I22: =+B22+C22+H22+G22 -> 11674
A23: POOR FUND | B23: =+'RECEIPTS AND PAYMENT ANANLYSIS'!N15 -> 2429.6 | I23: =+B23+C23+H23+G23 -> 2429.6
A24: MDF AWARENESS | B24: =+'RECEIPTS AND PAYMENT ANANLYSIS'!N16 -> 671 | C24: 0 | G24: 724 | H24: 242 | I24: =+B24+C24+H24+G24 -> 1637
A25: CIRCUIT HARVEST | B25: =+'RECEIPTS AND PAYMENT ANANLYSIS'!N17 -> 1011 | C25: 0 | G25: 0 | I25: =+B25+C25+H25+G25 -> 1011
A26: LAY MOVEMENT OFFERING | B26: =+'RECEIPTS AND PAYMENT ANANLYSIS'!N18 -> 0 | C26: 242 | G26: 40 | H26: 1450 | I26: =+B26+C26+H26+G26 -> 1732
A27: SPECIAL APPEAL | B27: =+'RECEIPTS AND PAYMENT ANANLYSIS'!N19 -> 1190 | C27: 140 | G27: 647 | I27: =+B27+C27+H27+G27 -> 1977
A28: WOMEN FELLOWSHIP | B28: =+'RECEIPTS AND PAYMENT ANANLYSIS'!N20 -> 2610 | C28: 0 | G28: 0 | H28: 13000 | I28: =+B28+C28+H28+G28 -> 15610
A29: OTHERS/NORTHERN GHANA | B29: =+'RECEIPTS AND PAYMENT ANANLYSIS'!N21 -> 0 | C29: 0 | G29: 80 | I29: =+B29+C29+H29+G29 -> 80
A30: AUTONOMY | B30: =+'RECEIPTS AND PAYMENT ANANLYSIS'!N22 -> 0 | C30: 0 | G30: 0 | H30: 140 | I30: =+B30+C30+H30+G30 -> 140
A31: WATCHNIGHT SERVICE | B31: =+'RECEIPTS AND PAYMENT ANANLYSIS'!N23 -> 0 | C31: 2011.5 | G31: 237 | I31: =+B31+C31+H31+G31 -> 2248.5
A32: CONVENANT SUNDAY | B32: =+'RECEIPTS AND PAYMENT ANANLYSIS'!N24 -> 535 | C32: 1220 | G32: 474.5 | I32: =+B32+C32+H32+G32 -> 2229.5
A33: TOTAL RECEIPTS | B33: =SUM(B16:B32) -> 396966.6 | C33: 258208.2 | G33: =SUM(G16:G32) -> 138973.8 | H33: =SUM(H16:H32) -> 66222.6 | I33: =SUM(I16:I32) -> 860371.2
A36: PAYMENT
A37: HONARARIUM TO PREACHERS | B37: =+'RECEIPTS AND PAYMENT ANANLYSIS'!N30 -> 15000 | C37: 11035 | G37: 8400 | H37: 750 | I37: =+B37+C37+H37+G37 -> 35185
A38: T&T | B38: =+'RECEIPTS AND PAYMENT ANANLYSIS'!N31 -> 2700 | C38: 1825 | G38: 285 | I38: =+B38+C38+H38+G38 -> 4810
A39: WELFARE | B39: =+'RECEIPTS AND PAYMENT ANANLYSIS'!N32 -> 4200 | C39: 4100 | G39: 250 | H39: 200 | I39: =+B39+C39+H39+G39 -> 8750
A40: FURNITURE | B40: =+'RECEIPTS AND PAYMENT ANANLYSIS'!N33 -> 28407.5 | C40: 0 | G40: 540 | H40: 500 | I40: =+B40+C40+H40+G40 -> 29447.5
A41: INSTRUMENTS | B41: =+'RECEIPTS AND PAYMENT ANANLYSIS'!N34 -> 11798 | C41: 0 | G41: 8390 | H41: 630 | I41: =+B41+C41+H41+G41 -> 20818
A42: MDF & SPECIAL OFFERING | B42: =+'RECEIPTS AND PAYMENT ANANLYSIS'!N35 -> 671 | C42: 2224 | G42: 2729 | H42: 242 | I42: =+B42+C42+H42+G42 -> 5866
A43: LAYMOVEMENT | B43: =+'RECEIPTS AND PAYMENT ANANLYSIS'!N36 -> 0 | C43: 242 | G43: 0 | I43: =+B43+C43+H43+G43 -> 242
A44: CIRCUIT HARVEST | B44: =+'RECEIPTS AND PAYMENT ANANLYSIS'!N37 -> 1199 | C44: 0 | G44: 0 | I44: =+B44+C44+H44+G44 -> 1199
...

Sheet TB
A1: HEBRON METHODIST CHURCH
A2: EXTENDED TRIAL BALANCE
A3: Account Code | C3: Details | D3: OPENING BALANCES | F3: CURRENT ACTIVITY | H3: ADJUSTMENT | J3: CLOSING BALANCES
B4: Non-current assets | D4: DR | E4: CR | F4: DR | G4: CR | H4: DR | I4: CR | J4: DR | K4: CR
D5: GHS | E5: GHS | F5: GHS | G5: GHS | H5: GHS | I5: GHS | J5: GHS | K5: GHS
A6: 00001 | C6: Office Building | J6: =+D6+F6+H6-E6-G6-I6 -> 0 | K6: =+E6+G6+I6-D6-F6-H6 -> 0
A7: 00002 | C7: Fixtures & fittings | J7: =+D7+F7+H7-E7-G7-I7 -> 0 | K7: =+E7+G7+I7-D7-F7-H7 -> 0
A8: 00003 | C8: Office equipment | J8: =+D8+F8+H8-E8-G8-I8 -> 0 | K8: =+E8+G8+I8-D8-F8-H8 -> 0
A9: 00004 | C9: Computers & accessories | J9: =+D9+F9+H9-E9-G9-I9 -> 0 | K9: =+E9+G9+I9-D9-F9-H9 -> 0
B10: Accummulative Depreciation | J10: =+D10+F10+H10-E10-G10-I10 -> 0 | K10: =+E10+G10+I10-D10-F10-H10 -> 0
A11: 00005 | C11: Office equipment | J11: =+D11+F11+H11-E11-G11-I11 -> 0 | K11: =+E11+G11+I11-D11-F11-H11 -> 0
A12: 00006 | C12: Computers & accessories | J12: =+D12+F12+H12-E12-G12-I12 -> 0 | K12: =+E12+G12+I12-D12-F12-H12 -> 0
C13: Fixtures & fittings | J13: =+D13+F13+H13-E13-G13-I13 -> 0 | K13: =+E13+G13+I13-D13-F13-H13 -> 0
B14: Intangible | J14: =+D14+F14+H14-E14-G14-I14 -> 0 | K14: =+E14+G14+I14-D14-F14-H14 -> 0
A15: 00007 | C15: Account Receivables | J15: =+D15+F15+H15-E15-G15-I15 -> 0 | K15: =+E15+G15+I15-D15-F15-H15 -> 0
J16: =+D16+F16+H16-E16-G16-I16 -> 0 | K16: =+E16+G16+I16-D16-F16-H16 -> 0
A17: 00008 | C17: Cash & Bank Equivalent | J17: =+D17+F17+H17-E17-G17-I17 -> 0 | K17: =+E17+G17+I17-D17-F17-H17 -> 0
A18: 00009 | C18: Cash at bank | J18: =+D18+F18+H18-E18-G18-I18 -> 0 | K18: =+E18+G18+I18-D18-F18-H18 -> 0
A19: 00010 | C19: Cash in hand | J19: =+D19+F19+H19-E19-G19-I19 -> 0 | K19: =+E19+G19+I19-D19-F19-H19 -> 0
J20: =+D20+F20+H20-E20-G20-I20 -> 0 | K20: =+E20+G20+I20-D20-F20-H20 -> 0
A21: 00011 | B21: Shareholders equity and liabilities | J21: =+D21+F21+H21-E21-G21-I21 -> 0 | K21: =+E21+G21+I21-D21-F21-H21 -> 0
A22: 00012 | C22: Current liabilities | J22: =+D22+F22+H22-E22-G22-I22 -> 0 | K22: =+E22+G22+I22-D22-F22-H22 -> 0
A23: 00013 | C23: Trade and other payables | J23: =+D23+F23+H23-E23-G23-I23 -> 0 | K23: =+E23+G23+I23-D23-F23-H23 -> 0
A24: 00014 | C24: Overdraft | J24: =+D24+F24+H24-E24-G24-I24 -> 0 | K24: =+E24+G24+I24-D24-F24-H24 -> 0
A25: 00015 | C25: Audit fees | J25: =+D25+F25+H25-E25-G25-I25 -> 0 | K25: =+E25+G25+I25-D25-F25-H25 -> 0
A26: 00016 | C26: Accrual-Rent | J26: =+D26+F26+H26-E26-G26-I26 -> 0 | K26: =+E26+G26+I26-D26-F26-H26 -> 0
A27: 00017 | C27: Accrual-PAYE | J27: =+D27+F27+H27-E27-G27-I27 -> 0 | K27: =+E27+G27+I27-D27-F27-H27 -> 0
A28: 00018 | C28: Long term loan | J28: =+D28+F28+H28-E28-G28-I28 -> 0 | K28: =+E28+G28+I28-D28-F28-H28 -> 0
A29: 00019 | C29: Stated capital | J29: =+D29+F29+H29-E29-G29-I29 -> 0 | K29: =+E29+G29+I29-D29-F29-H29 -> 0
A30: 00020 | C30: Amount held toward capital | J30: =+D30+F30+H30-E30-G30-I30 -> 0 | K30: =+E30+G30+I30-D30-F30-H30 -> 0
A31: 00021 | C31: Retained earnings | J31: =+D31+F31+H31-E31-G31-I31 -> 0 | K31: =+E31+G31+I31-D31-F31-H31 -> 0
B32: Revenue | J32: =+D32+F32+H32-E32-G32-I32 -> 0 | K32: =+E32+G32+I32-D32-F32-H32 -> 0
A33: 00022 | C33: Revenue | J33: =+D33+F33+H33-E33-G33-I33 -> 0 | K33: =+E33+G33+I33-D33-F33-H33 -> 0
A34: 00023 | C34: Foods and drinks | J34: =+D34+F34+H34-E34-G34-I34 -> 0 | K34: =+E34+G34+I34-D34-F34-H34 -> 0
J35: =+D35+F35+H35-E35-G35-I35 -> 0 | K35: =+E35+G35+I35-D35-F35-H35 -> 0
B36: Cost of sale | J36: =+D36+F36+H36-E36-G36-I36 -> 0 | K36: =+E36+G36+I36-D36-F36-H36 -> 0
A37: 00024 | C37: Cost of Ticket | J37: =+D37+F37+H37-E37-G37-I37 -> 0 | K37: =+E37+G37+I37-D37-F37-H37 -> 0
A38: 00025 | C38: Communication expenses | J38: =+D38+F38+H38-E38-G38-I38 -> 0 | K38: =+E38+G38+I38-D38-F38-H38 -> 0
A39: 00026 | C39: Depreciation | J39: =+D39+F39+H39-E39-G39-I39 -> 0 | K39: =+E39+G39+I39-D39-F39-H39 -> 0
A40: 00027 | C40: Utilites | J40: =+D40+F40+H40-E40-G40-I40 -> 0 | K40: =+E40+G40+I40-D40-F40-H40 -> 0
...

Sheet RECEIPTS AND PAYMENT ANANLYSIS
A1: =+'Rec & Pmt'!A1:C1 -> THE METHODIST CHURCH GHANA
A2: =+'Rec & Pmt'!A2:C2 -> ACCRA NORTH DIOCESE
A3: =+'Rec & Pmt'!A3:C3 -> GA SUB-URBAN CIRCUIT
A4: =+'Rec & Pmt'!A4:H4 -> HEBRON SOCIETY
A5: =+'Rec & Pmt'!A5:C5 -> STATEMENT OF ACCOUNT FOR THE PERIOD 1ST JANUARY,2024 TO 31ST DECEMBER,2024
B6: JAN | C6: FEB | D6: MAR | E6: APR | F6: MAY | G6: JUN | H6: JUL | I6: AUG | J6: SEP | K6: OCT | L6: NOV | M6: DEC | N6: TOTAL
A7: RECEIPTS | B7: GHC | C7: GHC | D7: GHC | E7: GHC | F7: GHC | G7: GHC | H7: GHC | I7: GHC | J7: GHC | K7: GHC | L7: GHC | M7: GHC | N7: GHC
A8: OFFERING | B8: ='weekly income statement'!C15 -> 2682.2 | C8: ='weekly income statement'!D15 -> 2715.3 | D8: ='weekly income statement'!E15 -> 4454.4 | E8: ='weekly income statement'!F15 -> 2965.6 | F8: ='weekly income statement'!G15 -> 2499.3 | G8: ='weekly income statement'!H15 -> 3969.5 | H8: ='weekly income statement'!I15 -> 2818.3 | I8: ='weekly income statement'!J15 -> 2336.5 | ... M8: ='weekly income statement'!N15 -> 5076.7 | N8: =B8+C8+D8+E8+F8+G8+H8+I8+J8+K8+L8+M8 -> 40490.5
A9: TITHE | B9: ='weekly income statement'!C23 -> 2085 | C9: ='weekly income statement'!D23 -> 9010 | D9: ='weekly income statement'!E23 -> 10180 | E9: ='weekly income statement'!F23 -> 5240 | F9: ='weekly income statement'!G23 -> 7405 | G9: ='weekly income statement'!H23 -> 9338 | H9: ='weekly income statement'!I23 -> 7218 | I9: ='weekly income statement'!J23 -> 3820 | ... M9: ='weekly income statement'!N23 -> 9715 | N9: =B9+C9+D9+E9+F9+G9+H9+I9+J9+K9+L9+M9 -> 96711
A10: WEEKDAY ACTIVITY | B10: ='weekly income statement'!C36 -> 482.6 | C10: ='weekly income statement'!D36 -> 260 | D10: ='weekly income statement'!E36 -> 218.5 | E10: ='weekly income statement'!F36 -> 0 | F10: ='weekly income statement'!G36 -> 0 | G10: ='weekly income statement'!H36 -> 0 | H10: ='weekly income statement'!I36 -> 55 | I10: ='weekly income statement'!J36 -> 306 | ... M10: ='weekly income statement'!N36 -> 435 | N10: =B10+C10+D10+E10+F10+G10+H10+I10+J10+K10+L10+M10 -> 2772.1 | S10: 2110
A11: THANKS OFFERING | B11: ='weekly income statement'!C44 -> 350 | C11: ='weekly income statement'!D44 -> 200 | D11: ='weekly income statement'!E44 -> 50 | E11: ='weekly income statement'!F44 -> 100 | F11: ='weekly income statement'!G44 -> 250 | G11: ='weekly income statement'!H44 -> 0 | H11: ='weekly income statement'!I44 -> 310 | I11: ='weekly income statement'!J44 -> 350 | ... M11: ='weekly income statement'!N44 -> 1050 | N11: =B11+C11+D11+E11+F11+G11+H11+I11+J11+K11+L11+M11 -> 4490 | S11: 880
A12: HARVEST | B12: ='weekly income statement'!C52 -> 0 | C12: ='weekly income statement'!D52 -> 12134.9 | D12: ='weekly income statement'!E52 -> 47785 | E12: ='weekly income statement'!F52 -> 15950 | F12: ='weekly income statement'!G52 -> 3890 | G12: ='weekly income statement'!H52 -> 40200 | H12: ='weekly income statement'!I52 -> 630 | I12: ='weekly income statement'!J52 -> 100 | ... M12: ='weekly income statement'!N52 -> 58680 | N12: =B12+C12+D12+E12+F12+G12+H12+I12+J12+K12+L12+M12 -> 238458.9 | S12: 660
A13: WELFARE | B13: ='weekly income statement'!C54 -> 0 | C13: ='weekly income statement'!D54 -> 0 | D13: ='weekly income statement'!E54 -> 0 | E13: ='weekly income statement'!F54 -> 0 | F13: ='weekly income statement'!G54 -> 2970 | G13: ='weekly income statement'!H54 -> 334 | H13: ='weekly income statement'!I54 -> 513.5 | I13: ='weekly income statement'!J54 -> 347 | ... M13: ='weekly income statement'!N54 -> 0 | N13: =B13+C13+D13+E13+F13+G13+H13+I13+J13+K13+L13+M13 -> 4704.5
A14: SPECIAL OFFERING | B14: ='weekly income statement'!C55 -> 0 | C14: ='weekly income statement'!D55 -> 0 | D14: ='weekly income statement'!E55 -> 0 | E14: ='weekly income statement'!F55 -> 432 | F14: ='weekly income statement'!G55 -> 0 | G14: ='weekly income statement'!H55 -> 0 | H14: ='weekly income statement'!I55 -> 190 | I14: ='weekly income statement'!J55 -> 70 | ... M14: ='weekly income statement'!N55 -> 191 | N14: =B14+C14+D14+E14+F14+G14+H14+I14+J14+K14+L14+M14 -> 893 | S14: 100
A15: POOR FUND | B15: ='weekly income statement'!C56 -> 0 | C15: ='weekly income statement'!D56 -> 0 | D15: ='weekly income statement'!E56 -> 0 | E15: ='weekly income statement'!F56 -> 584 | F15: ='weekly income statement'!G56 -> 210 | G15: ='weekly income statement'!H56 -> 253 | H15: ='weekly income statement'!I56 -> 0 | I15: ='weekly income statement'!J56 -> 75 | ... M15: ='weekly income statement'!N56 -> 0 | N15: =B15+C15+D15+E15+F15+G15+H15+I15+J15+K15+L15+M15 -> 2429.6
A16: MDF AWARENESS | B16: ='weekly income statement'!C57 -> 0 | C16: ='weekly income statement'!D57 -> 0 | D16: ='weekly income statement'!E57 -> 0 | E16: ='weekly income statement'!F57 -> 0 | F16: ='weekly income statement'!G57 -> 0 | G16: ='weekly income statement'!H57 -> 0 | H16: ='weekly income statement'!I57 -> 0 | I16: ='weekly income statement'!J57 -> 0 | ... M16: ='weekly income statement'!N57 -> 0 | N16: =B16+C16+D16+E16+F16+G16+H16+I16+J16+K16+L16+M16 -> 671 | S16: =SUM(S10:S14) -> 3750
A17: CIRCUIT HARVEST | B17: ='weekly income statement'!C58 -> 0 | C17: ='weekly income statement'!D58 -> 0 | D17: ='weekly income statement'!E58 -> 661 | E17: ='weekly income statement'!F58 -> 0 | F17: ='weekly income statement'!G58 -> 350 | G17: ='weekly income statement'!H58 -> 0 | H17: ='weekly income statement'!I58 -> 0 | I17: ='weekly income statement'!J58 -> 0 | ... M17: ='weekly income statement'!N58 -> 0 | N17: =B17+C17+D17+E17+F17+G17+H17+I17+J17+K17+L17+M17 -> 1011
A18: LAY MOVEMENT OFFERING | B18: ='weekly income statement'!C59 -> 0 | C18: ='weekly income statement'!D59 -> 0 | D18: ='weekly income statement'!E59 -> 0 | E18: ='weekly income statement'!F59 -> 0 | F18: ='weekly income statement'!G59 -> 0 | G18: ='weekly income statement'!H59 -> 0 | H18: ='weekly income statement'!I59 -> 0 | I18: ='weekly income statement'!J59 -> 0 | ... M18: ='weekly income statement'!N59 -> 0 | N18: =B18+C18+D18+E18+F18+G18+H18+I18+J18+K18+L18+M18 -> 0
A19: SPECIAL APPEAL | B19: ='weekly income statement'!C60 -> 0 | C19: ='weekly income statement'!D60 -> 0 | D19: ='weekly income statement'!E60 -> 0 | E19: ='weekly income statement'!F60 -> 1190 | F19: ='weekly income statement'!G60 -> 0 | G19: ='weekly income statement'!H60 -> 0 | H19: ='weekly income statement'!I60 -> 0 | I19: ='weekly income statement'!J60 -> 0 | ... M19: ='weekly income statement'!N60 -> 0 | N19: =B19+C19+D19+E19+F19+G19+H19+I19+J19+K19+L19+M19 -> 1190
A20: WOMEN FELLOWSHIP | B20: ='weekly income statement'!C61 -> 0 | C20: ='weekly income statement'!D61 -> 0 | D20: ='weekly income statement'!E61 -> 0 | E20: ='weekly income statement'!F61 -> 0 | F20: ='weekly income statement'!G61 -> 0 | G20: ='weekly income statement'!H61 -> 0 | H20: ='weekly income statement'!I61 -> 2610 | I20: ='weekly income statement'!J61 -> 0 | ... M20: ='weekly income statement'!N61 -> 0 | N20: =B20+C20+D20+E20+F20+G20+H20+I20+J20+K20+L20+M20 -> 2610
A21: OTHERS/NORTHERN GHANA | B21: ='weekly income statement'!C62 -> 0 | C21: ='weekly income statement'!D62 -> 0 | D21: ='weekly income statement'!E62 -> 0 | E21: ='weekly income statement'!F62 -> 0 | F21: ='weekly income statement'!G62 -> 0 | G21: ='weekly income statement'!H62 -> 0 | H21: ='weekly income statement'!I62 -> 0 | I21: ='weekly income statement'!J62 -> 0 | ... M21: ='weekly income statement'!N62 -> 0 | N21: =B21+C21+D21+E21+F21+G21+H21+I21+J21+K21+L21+M21 -> 0
A22: AUTONOMY | B22: ='weekly income statement'!C63 -> 0 | C22: ='weekly income statement'!D63 -> 0 | D22: ='weekly income statement'!E63 -> 0 | E22: ='weekly income statement'!F63 -> 0 | F22: ='weekly income statement'!G63 -> 0 | G22: ='weekly income statement'!H63 -> 0 | H22: ='weekly income statement'!I63 -> 0 | I22: ='weekly income statement'!J63 -> 0 | ... M22: ='weekly income statement'!N63 -> 0 | N22: =B22+C22+D22+E22+F22+G22+H22+I22+J22+K22+L22+M22 -> 0
A23: WATCHNIGHT SERVICE | B23: ='weekly income statement'!C64 -> 0 | C23: ='weekly income statement'!D64 -> 0 | D23: ='weekly income statement'!E64 -> 0 | E23: ='weekly income statement'!F64 -> 0 | F23: ='weekly income statement'!G64 -> 0 | G23: ='weekly income statement'!H64 -> 0 | H23: ='weekly income statement'!I64 -> 0 | I23: ='weekly income statement'!J64 -> 0 | ... M23: ='weekly income statement'!N64 -> 0 | N23: =B23+C23+D23+E23+F23+G23+H23+I23+J23+K23+L23+M23 -> 0
A24: CONVENANT SUNDAY | B24: ='weekly income statement'!C65 -> 535 | C24: ='weekly income statement'!D65 -> 0 | D24: ='weekly income statement'!E65 -> 0 | E24: ='weekly income statement'!F65 -> 0 | F24: ='weekly income statement'!G65 -> 0 | G24: ='weekly income statement'!H65 -> 0 | H24: ='weekly income statement'!I65 -> 0 | I24: ='weekly income statement'!J65 -> 0 | ... M24: ='weekly income statement'!N65 -> 0 | N24: =B24+C24+D24+E24+F24+G24+H24+I24+J24+K24+L24+M24 -> 535
B27: =SUM(B8:B24) -> 6134.8 | C27: =SUM(C8:C24) -> 24320.2 | D27: =SUM(D8:D24) -> 63348.9 | E27: =SUM(E8:E24) -> 26461.6 | F27: =SUM(F8:F24) -> 17574.3 | G27: =SUM(G8:G24) -> 54094.5 | H27: =SUM(H8:H24) -> 14344.8 | I27: =SUM(I8:I24) -> 7404.5 | ... N27: =SUM(N8:N24) -> 396966.6
A29: EXPENDITURE
A30: HONARARIUM TO PREACHERS | B30: =Expend!C15 -> 500 | C30: =Expend!D15 -> 450 | D30: =Expend!E15 -> 2300 | E30: =Expend!F15 -> 400 | F30: =Expend!G15 -> 950 | G30: =Expend!H15 -> 4100 | H30: =Expend!I15 -> 1800 | I30: =Expend!J15 -> 1000 | ... M30: =Expend!N15 -> 1100 | N30: =B30+C30+D30+E30+F30+G30+H30+I30+J30+K30+L30+M30 -> 15000
A31: T&T | B31: =Expend!C22 -> 200 | C31: =Expend!D22 -> 0 | D31: =Expend!E22 -> 0 | E31: =Expend!F22 -> 900 | F31: =Expend!G22 -> 1200 | G31: =Expend!H22 -> 0 | H31: =Expend!I22 -> 400 | I31: =Expend!J22 -> 0 | ... M31: =Expend!N22 -> 0 | N31: =B31+C31+D31+E31+F31+G31+H31+I31+J31+K31+L31+M31 -> 2700
A32: WELFARE | B32: =Expend!C29 -> 200 | C32: =Expend!D29 -> 0 | D32: =Expend!E29 -> 700 | E32: =Expend!F29 -> 0 | F32: =Expend!G29 -> 300 | G32: =Expend!H29 -> 200 | H32: =Expend!I29 -> 0 | I32: =Expend!J29 -> 300 | ... M32: =Expend!N29 -> 200 | N32: =B32+C32+D32+E32+F32+G32+H32+I32+J32+K32+L32+M32 -> 4200
A33: FURNITURE | B33: =Expend!C34 -> 0 | C33: =Expend!D34 -> 0 | D33: =Expend!E34 -> 0 | E33: =Expend!F34 -> 0 | F33: =Expend!G34 -> 0 | G33: =Expend!H34 -> 3440 | H33: =Expend!I34 -> 0 | I33: =Expend!J34 -> 0 | ... M33: =Expend!N34 -> 5300 | N33: =B33+C33+D33+E33+F33+G33+H33+I33+J33+K33+L33+M33 -> 28407.5
A34: INSTRUMENTS | B34: =Expend!C35 -> 0 | C34: =Expend!D35 -> 0 | D34: =Expend!E35 -> 3000 | E34: =Expend!F35 -> 550 | F34: =Expend!G35 -> 4650 | G34: =Expend!H35 -> 0 | H34: =Expend!I35 -> 0 | I34: =Expend!J35 -> 0 | ... M34: =Expend!N35 -> 400 | N34: =B34+C34+D34+E34+F34+G34+H34+I34+J34+K34+L34+M34 -> 11798
A35: MDF | B35: =Expend!C36 -> 0 | C35: =Expend!D36 -> 0 | D35: =Expend!E36 -> 0 | E35: =Expend!F36 -> 0 | F35: =Expend!G36 -> 0 | G35: =Expend!H36 -> 0 | H35: =Expend!I36 -> 0 | I35: =Expend!J36 -> 0 | ... M35: =Expend!N36 -> 0 | N35: =B35+C35+D35+E35+F35+G35+H35+I35+J35+K35+L35+M35 -> 671
A36: LAYMOVEMENT | B36: =Expend!C37 -> 0 | C36: =Expend!D37 -> 0 | D36: =Expend!E37 -> 0 | E36: =Expend!F37 -> 0 | F36: =Expend!G37 -> 0 | G36: =Expend!H37 -> 0 | H36: =Expend!I37 -> 0 | I36: =Expend!J37 -> 0 | ... M36: =Expend!N37 -> 0 | N36: =B36+C36+D36+E36+F36+G36+H36+I36+J36+K36+L36+M36 -> 0
A37: CIRCUIT HARVEST | B37: =Expend!C38 -> 0 | C37: =Expend!D38 -> 188 | D37: =Expend!E38 -> 661 | E37: =Expend!F38 -> 0 | F37: =Expend!G38 -> 350 | G37: =Expend!H38 -> 0 | H37: =Expend!I38 -> 0 | I37: =Expend!J38 -> 0 | ... M37: =Expend!N38 -> 0 | N37: =B37+C37+D37+E37+F37+G37+H37+I37+J37+K37+L37+M37 -> 1199
A38: DONATIONS | B38: =Expend!C39 -> 0 | C38: =Expend!D39 -> 0 | D38: =Expend!E39 -> 0 | E38: =Expend!F39 -> 0 | F38: =Expend!G39 -> 0 | G38: =Expend!H39 -> 0 | H38: =Expend!I39 -> 0 | I38: =Expend!J39 -> 0 | ... M38: =Expend!N39 -> 2050 | N38: =B38+C38+D38+E38+F38+G38+H38+I38+J38+K38+L38+M38 -> 3050
A39: MINISTERS APPRECIATION | B39: =Expend!C40 -> 0 | C39: =Expend!D40 -> 0 | D39: =Expend!E40 -> 0 | E39: =Expend!F40 -> 0 | F39: =Expend!G40 -> 0 | G39: =Expend!H40 -> 0 | H39: =Expend!I40 -> 0 | I39: =Expend!J40 -> 0 | ... M39: =Expend!N40 -> 0 | N39: =B39+C39+D39+E39+F39+G39+H39+I39+J39+K39+L39+M39 -> 0
A40: PURCHASE OF METHODIST STATIONARY | B40: =Expend!C41 -> 160 | C40: =Expend!D41 -> 280 | D40: =Expend!E41 -> 1100 | E40: =Expend!F41 -> 70 | F40: =Expend!G41 -> 0 | G40: =Expend!H41 -> 0 | H40: =Expend!I41 -> 500 | I40: =Expend!J41 -> 0 | ... M40: =Expend!N41 -> 0 | N40: =B40+C40+D40+E40+F40+G40+H40+I40+J40+K40+L40+M40 -> 2110
A41: DIOCESAN APPEAL(CHILD WEEK) | B41: =Expend!C42 -> 0 | C41: =Expend!D42 -> 0 | D41: =Expend!E42 -> 0 | E41: =Expend!F42 -> 0 | F41: =Expend!G42 -> 0 | G41: =Expend!H42 -> 0 | H41: =Expend!I42 -> 0 | I41: =Expend!J42 -> 0 | ... M41: =Expend!N42 -> 0 | N41: =B41+C41+D41+E41+F41+G41+H41+I41+J41+K41+L41+M41 -> 0
A42: =+Expend!B47 -> WATER & ECG | B42: =+Expend!C47 -> 0 | C42: =+Expend!D47 -> 0 | D42: =+Expend!E47 -> 0 | E42: =+Expend!F47 -> 0 | F42: =+Expend!G47 -> 0 | G42: =+Expend!H47 -> 0 | H42: =+Expend!I47 -> 300 | ... M42: =+Expend!N47 -> 300 | N42: =B42+C42+D42+E42+F42+G42+H42+I42+J42+K42+L42+M42 -> 600
A43: LAND | B43: =Expend!C80 -> 0 | C43: =Expend!D80 -> 0 | D43: =Expend!E80 -> 200 | E43: =Expend!F80 -> 0 | F43: =Expend!G80 -> 0 | G43: =Expend!H80 -> 0 | H43: =Expend!I80 -> 0 | I43: =Expend!J80 -> 0 | ... M43: =Expend!N80 -> 20000 | N43: =B43+C43+D43+E43+F43+G43+H43+I43+J43+K43+L43+M43 -> 66200
...

Sheet weekly income statement
A1: =+'RECEIPTS AND PAYMENT ANANLYSIS'!A1:N1 -> THE METHODIST CHURCH GHANA
A2: =+'RECEIPTS AND PAYMENT ANANLYSIS'!A2:N2 -> ACCRA NORTH DIOCESE
A3: =+'RECEIPTS AND PAYMENT ANANLYSIS'!A3:N3 -> GA SUB-URBAN CIRCUIT
A4: =+'RECEIPTS AND PAYMENT ANANLYSIS'!A4:N4 -> HEBRON SOCIETY
A5: =+'RECEIPTS AND PAYMENT ANANLYSIS'!A5:N5 -> STATEMENT OF ACCOUNT FOR THE PERIOD 1ST JANUARY,2024 TO 31ST DECEMBER,2024
A7: S/N | B7: NAME | C7: JAN | D7: FEB | E7: MAR | F7: APR | G7: MAY | H7: JUN | I7: JUL | J7: AUG | K7: SEP | L7: OCT | M7: NOV | N7: DEC | O7: TOTAL
A8: DATE | C8: GHC | D8: GHC | E8: GHC | F8: GHC | G8: GHC | H8: GHC | I8: GHC | J8: GHC | K8: GHC | L8: GHC | M8: GHC | N8: GHC | O8: GHC
B9: OFFERING | C9: 0 | O9: =C9+D9+E9+F9+G9+H9+I9+J9+K9+L9+M9+N9 -> 0
A10: WK 1 | C10: 215 | D10: =437+111.5 -> 548.5 | E10: =483.7+128.5 -> 612.2 | F10: =495+104 -> 599 | G10: 757.1 | H10: =736+114 -> 850 | I10: 846 | J10: 542.3 | K10: =132+573 -> 705 | L10: =780+137.6 -> 917.6 | M10: =785+55.4 -> 840.4 | N10: 830 | O10: =C10+D10+E10+F10+G10+H10+I10+J10+K10+L10+M10+N10 -> 8263.1
A11: WK 2 | C11: =609+112.7 -> 721.7 | D11: =687+86.1 -> 773.1 | E11: =511.5+109.5 -> 621 | F11: 865.5 | G11: =395.7+106.5 -> 502.2 | H11: =754+70.8 -> 824.8 | I11: =522.5+137.4 -> 659.9 | J11: 496.5 | K11: =748.5+100.5 -> 849 | L11: =754.5+54 -> 808.5 | M11: =619+151.9 -> 770.9 | N11: =666+151.5 -> 817.5 | O11: =C11+D11+E11+F11+G11+H11+I11+J11+K11+L11+M11+N11 -> 8710.6
A12: WK 3 | C12: =662+214 -> 876 | D12: 238 | E12: =649+156.5 -> 805.5 | F12: =696.3+153.9 -> 850.2 | G12: =702.5+105 -> 807.5 | H12: =772+131.5 -> 903.5 | I12: 774 | J12: =643.4+89.2 -> 732.6 | K12: 815.7 | L12: =614.5+282.1+51 -> 947.6 | M12: =774.2+146.9 -> 921.1 | N12: =926+139.3 -> 1065.3 | O12: =C12+D12+E12+F12+G12+H12+I12+J12+K12+L12+M12+N12 -> 9737
A13: WK 4 | C13: 869.5 | D13: 538 | E13: =673+128.7 -> 801.7 | F13: =539+111.9 -> 650.9 | G13: =355+77.5 -> 432.5 | H13: =420+147.5 -> 567.5 | I13: =436.4+102 -> 538.4 | J13: =416+149.1 -> 565.1 | K13: 1032.2 | L13: =602+101 -> 703 | M13: =774+113 -> 887 | N13: =703+532+135.4 -> 1370.4 | O13: =C13+D13+E13+F13+G13+H13+I13+J13+K13+L13+M13+N13 -> 8956.2
A14: WK 5 | D14: =476.2+141.5 -> 617.7 | E14: =864.5+625.5+124 -> 1614 | H14: =681.7+142 -> 823.7 | K14: =666.5+108.2 -> 774.7 | N14: =953.5+40 -> 993.5 | O14: =C14+D14+E14+F14+G14+H14+I14+J14+K14+L14+M14+N14 -> 4823.6
C15: =SUM(C9:C14) -> 2682.2 | D15: =SUM(D9:D14) -> 2715.3 | E15: =SUM(E9:E14) -> 4454.4 | F15: =SUM(F9:F14) -> 2965.6 | G15: =SUM(G9:G14) -> 2499.3 | H15: =SUM(H9:H14) -> 3969.5 | I15: =SUM(I9:I14) -> 2818.3 | J15: =SUM(J9:J14) -> 2336.5 | ... N15: =SUM(N9:N14) -> 5076.7 | O15: =C15+D15+E15+F15+G15+H15+I15+J15+K15+L15+M15+N15 -> 40490.5
O16: =C16+D16+E16+F16+G16+H16+I16+J16+K16+L16+M16+N16 -> 0
B17: TITHE | C17: 0 | O17: =C17+D17+E17+F17+G17+H17+I17+J17+K17+L17+M17+N17 -> 0
A18: WK 1 | C18: 450 | D18: 4775 | E18: 970 | F18: 1120 | G18: 2820 | H18: 4510 | I18: 3978 | J18: 900 | K18: 5570 | L18: 3340 | M18: 2590 | N18: 2490 | O18: =C18+D18+E18+F18+G18+H18+I18+J18+K18+L18+M18+N18 -> 33513
A19: WK 2 | C19: 840 | D19: 265 | E19: 3555 | F19: 1550 | G19: 4265 | H19: 3448 | I19: 2850 | J19: 1010 | K19: 5380 | L19: 4680 | M19: 4610 | N19: 3240 | O19: =C19+D19+E19+F19+G19+H19+I19+J19+K19+L19+M19+N19 -> 35693
A20: WK 3 | C20: 795 | D20: 1050 | E20: 280 | F20: 1700 | G20: 100 | H20: 410 | I20: 270 | J20: 420 | K20: 900 | L20: 60 | M20: 890 | N20: 2840 | O20: =C20+D20+E20+F20+G20+H20+I20+J20+K20+L20+M20+N20 -> 9715
A21: WK 4 | D21: =2360+560 -> 2920 | E21: 650 | F21: 870 | G21: 220 | H21: 520 | I21: 120 | J21: 1490 | K21: 1550 | L21: 1020 | M21: 2010 | N21: 745 | O21: =C21+D21+E21+F21+G21+H21+I21+J21+K21+L21+M21+N21 -> 12115
A22: WK 5 | E22: =4325+400 -> 4725 | H22: 450 | K22: 100 | N22: 400 | O22: =C22+D22+E22+F22+G22+H22+I22+J22+K22+L22+M22+N22 -> 5675
C23: =SUM(C17:C22) -> 2085 | D23: =SUM(D17:D22) -> 9010 | E23: =SUM(E17:E22) -> 10180 | F23: =SUM(F17:F22) -> 5240 | G23: =SUM(G17:G22) -> 7405 | H23: =SUM(H17:H22) -> 9338 | I23: =SUM(I17:I22) -> 7218 | J23: =SUM(J17:J22) -> 3820 | ... N23: =SUM(N17:N22) -> 9715 | O23: =C23+D23+E23+F23+G23+H23+I23+J23+K23+L23+M23+N23 -> 96711
B25: WEEK DAY OFFERING | O25: =C25+D25+E25+F25+G25+H25+I25+J25+K25+L25+M25+N25 -> 0
A26: WK 1 | B26: WEDNESDAY | C26: 75 | D26: 55 | J26: 45 | K26: 80 | L26: 176 | M26: 42 | O26: =C26+D26+E26+F26+G26+H26+I26+J26+K26+L26+M26+N26 -> 473
B27: FRIDAY | C27: 57 | D27: 75 | E27: 55 | J27: 53 | K27: 35 | L27: 161 | M27: 102 | N27: 55 | O27: =C27+D27+E27+F27+G27+H27+I27+J27+K27+L27+M27+N27 -> 593
A28: WK 2 | B28: WEDNESDAY | C28: 55 | D28: 65 | E28: 41 | J28: 85 | K28: 80 | M28: 116 | N28: 110 | O28: =C28+D28+E28+F28+G28+H28+I28+J28+K28+L28+M28+N28 -> 552
B29: FRIDAY | C29: 102 | D29: 30 | E29: 31 | J29: 30 | K29: 50 | M29: 113 | N29: 57 | O29: =C29+D29+E29+F29+G29+H29+I29+J29+K29+L29+M29+N29 -> 413
A30: WK 3 | B30: WEDNESDAY | C30: 137.4 | D30: 35 | E30: 91.5 | J30: 53 | K30: 30 | N30: 213 | O30: =C30+D30+E30+F30+G30+H30+I30+J30+K30+L30+M30+N30 -> 559.9
B31: FRIDAY | C31: 56.2 | I31: 55 | J31: 40 | K31: 30 | O31: =C31+D31+E31+F31+G31+H31+I31+J31+K31+L31+M31+N31 -> 181.2
A32: WK 4 | B32: WEDNESDAY | O32: =C32+D32+E32+F32+G32+H32+I32+J32+K32+L32+M32+N32 -> 0
B33: FRIDAY | O33: =C33+D33+E33+F33+G33+H33+I33+J33+K33+L33+M33+N33 -> 0
A34: WK 5 | B34: WEDNESDAY | O34: =C34+D34+E34+F34+G34+H34+I34+J34+K34+L34+M34+N34 -> 0
B35: FRIDAY | O35: =C35+D35+E35+F35+G35+H35+I35+J35+K35+L35+M35+N35 -> 0
C36: =SUM(C25:C35) -> 482.6 | D36: =SUM(D25:D35) -> 260 | E36: =SUM(E25:E35) -> 218.5 | F36: =SUM(F25:F35) -> 0 | G36: =SUM(G25:G35) -> 0 | H36: =SUM(H25:H35) -> 0 | I36: =SUM(I25:I35) -> 55 | J36: =SUM(J25:J35) -> 306 | ... N36: =SUM(N25:N35) -> 435 | O36: =C36+D36+E36+F36+G36+H36+I36+J36+K36+L36+M36+N36 -> 2772.1
O37: =C37+D37+E37+F37+G37+H37+I37+J37+K37+L37+M37+N37 -> 0
B38: THANKS OFFERING | C38: 300 | D38: 200 | E38: 50 | F38: 50 | G38: 250 | I38: 200 | J38: 200 | K38: 500 | L38: 200 | M38: 100 | N38: 50 | O38: =C38+D38+E38+F38+G38+H38+I38+J38+K38+L38+M38+N38 -> 2100
C39: 50 | F39: 50 | I39: 110 | J39: 150 | K39: 80 | L39: 100 | M39: 250 | N39: 700 | O39: =C39+D39+E39+F39+G39+H39+I39+J39+K39+L39+M39+N39 -> 1490
K40: 50 | L40: 200 | M40: 50 | N40: 100 | O40: =C40+D40+E40+F40+G40+H40+I40+J40+K40+L40+M40+N40 -> 400
K41: 200 | N41: 200 | O41: =C41+D41+E41+F41+G41+H41+I41+J41+K41+L41+M41+N41 -> 400
K42: 100 | O42: =C42+D42+E42+F42+G42+H42+I42+J42+K42+L42+M42+N42 -> 100
...

Sheet Expend
A1: =+'weekly income statement'!A1:O1 -> THE METHODIST CHURCH GHANA
A2: =+'weekly income statement'!A2:O2 -> ACCRA NORTH DIOCESE
A3: =+'weekly income statement'!A3:O3 -> GA SUB-URBAN CIRCUIT
A4: =+'weekly income statement'!A4:O4 -> HEBRON SOCIETY
A5: =+'weekly income statement'!A5:O5 -> STATEMENT OF ACCOUNT FOR THE PERIOD 1ST JANUARY,2024 TO 31ST DECEMBER,2024
A6: rev
A8: S/N | B8: NAME | C8: JAN | D8: FEB | E8: MAR | F8: APR | G8: MAY | H8: JUN | I8: JUL | J8: AUG | K8: SEP | L8: OCT | M8: NOV | N8: DEC | O8: TOTAL
C9: GHC | D9: GHC | E9: GHC | F9: GHC | G9: GHC | H9: GHC | I9: GHC | J9: GHC | K9: GHC | L9: GHC | M9: GHC | N9: GHC | O9: GHC
B10: HONARARIUM TO PREACHERS | C10: 100 | D10: 100 | E10: 600 | F10: 50 | G10: 650 | H10: 400 | I10: 100 | J10: 100 | K10: 400 | L10: 200 | M10: 100 | N10: 500 | O10: =C10+D10+E10+F10+G10+H10+I10+J10+K10+L10+M10+N10 -> 3300
C11: 400 | D11: 50 | E11: 100 | F11: 100 | G11: 100 | H11: 100 | I11: 200 | J11: 200 | K11: 100 | L11: 100 | M11: 100 | N11: 200 | O11: =C11+D11+E11+F11+G11+H11+I11+J11+K11+L11+M11+N11 -> 1750
D12: =200+50 -> 250 | E12: 1000 | F12: 50 | H12: 200 | I12: 100 | J12: 200 | K12: 150 | L12: 200 | M12: 100 | N12: 200 | O12: =C12+D12+E12+F12+G12+H12+I12+J12+K12+L12+M12+N12 -> 2450
D13: 50 | E13: 600 | F13: 200 | G13: 200 | H13: 400 | I13: 1000 | J13: 500 | K13: 450 | L13: 200 | M13: 200 | N13: 200 | O13: =C13+D13+E13+F13+G13+H13+I13+J13+K13+L13+M13+N13 -> 4000
H14: 3000 | I14: 400 | L14: 100 | N14: 0 | O14: =C14+D14+E14+F14+G14+H14+I14+J14+K14+L14+M14+N14 -> 3500
C15: =SUM(C10:C14) -> 500 | D15: =SUM(D10:D14) -> 450 | E15: =SUM(E10:E14) -> 2300 | F15: =SUM(F10:F14) -> 400 | G15: =SUM(G10:G14) -> 950 | H15: =SUM(H10:H14) -> 4100 | I15: =SUM(I10:I14) -> 1800 | J15: =SUM(J10:J14) -> 1000 | ... N15: =SUM(N10:N14) -> 1100 | O15: =C15+D15+E15+F15+G15+H15+I15+J15+K15+L15+M15+N15 -> 15000
O16: =C16+D16+E16+F16+G16+H16+I16+J16+K16+L16+M16+N16 -> 0
B17: T&T TO CIRCUIT & SESSIONAL EVENTS | C17: 200 | F17: 900 | G17: 1200 | I17: 400 | O17: =C17+D17+E17+F17+G17+H17+I17+J17+K17+L17+M17+N17 -> 2700
O18: =C18+D18+E18+F18+G18+H18+I18+J18+K18+L18+M18+N18 -> 0
O19: =C19+D19+E19+F19+G19+H19+I19+J19+K19+L19+M19+N19 -> 0
O20: =C20+D20+E20+F20+G20+H20+I20+J20+K20+L20+M20+N20 -> 0
O21: =C21+D21+E21+F21+G21+H21+I21+J21+K21+L21+M21+N21 -> 0
C22: =SUM(C17:C21) -> 200 | D22: =SUM(D17:D21) -> 0 | E22: =SUM(E17:E21) -> 0 | F22: =SUM(F17:F21) -> 900 | G22: =SUM(G17:G21) -> 1200 | H22: =SUM(H17:H21) -> 0 | I22: =SUM(I17:I21) -> 400 | J22: =SUM(J17:J21) -> 0 | ... N22: =SUM(N17:N21) -> 0 | O22: =C22+D22+E22+F22+G22+H22+I22+J22+K22+L22+M22+N22 -> 2700
O23: =C23+D23+E23+F23+G23+H23+I23+J23+K23+L23+M23+N23 -> 0
B24: WELFARE | C24: 200 | E24: 200 | G24: 300 | H24: 200 | J24: =100+200 -> 300 | K24: 400 | L24: 200 | M24: =200+1000 -> 1200 | N24: 200 | O24: =C24+D24+E24+F24+G24+H24+I24+J24+K24+L24+M24+N24 -> 3200
E25: 500 | M25: 500 | O25: =C25+D25+E25+F25+G25+H25+I25+J25+K25+L25+M25+N25 -> 1000
O26: =C26+D26+E26+F26+G26+H26+I26+J26+K26+L26+M26+N26 -> 0
O27: =C27+D27+E27+F27+G27+H27+I27+J27+K27+L27+M27+N27 -> 0
O28: =C28+D28+E28+F28+G28+H28+I28+J28+K28+L28+M28+N28 -> 0
C29: =SUM(C24:C28) -> 200 | D29: =SUM(D24:D28) -> 0 | E29: =SUM(E24:E28) -> 700 | F29: =SUM(F24:F28) -> 0 | G29: =SUM(G24:G28) -> 300 | H29: =SUM(H24:H28) -> 200 | I29: =SUM(I24:I28) -> 0 | J29: =SUM(J24:J28) -> 300 | ... N29: =SUM(N24:N28) -> 200 | O29: =C29+D29+E29+F29+G29+H29+I29+J29+K29+L29+M29+N29 -> 4200
D30: 0 | F30: =SUM(F29) -> 0
B34: PURCHASE OF FURNITURE | H34: 3440 | M34: =5400+3500+3129.3+1618.2+120+600+3900+300+1100 -> 19667.5 | N34: 5300 | O34: =C34+D34+E34+F34+G34+H34+I34+J34+K34+L34+M34+N34 -> 28407.5
B35: PURCHASE OF INSTRUMENTS | E35: 3000 | F35: 550 | G35: =750+400+3500 -> 4650 | M35: =1147+500+1251+300 -> 3198 | N35: 400 | O35: =C35+D35+E35+F35+G35+H35+I35+J35+K35+L35+M35+N35 -> 11798
B36: PAYMENT OF MDF/SPECIAL APPEAL | M36: 671 | O36: =C36+D36+E36+F36+G36+H36+I36+J36+K36+L36+M36+N36 -> 671
B37: PAYMENT OF LAYMOVEMENT FUNDS | O37: =C37+D37+E37+F37+G37+H37+I37+J37+K37+L37+M37+N37 -> 0
B38: PAYMENT OF CIRCUIT HARVEST | D38: 188 | E38: 661 | G38: 350 | O38: =C38+D38+E38+F38+G38+H38+I38+J38+K38+L38+M38+N38 -> 1199
B39: DONATION | K39: =500+300+200 -> 1000 | N39: 2050 | O39: =C39+D39+E39+F39+G39+H39+I39+J39+K39+L39+M39+N39 -> 3050
B40: MINISTERS APPRECIATION | O40: =C40+D40+E40+F40+G40+H40+I40+J40+K40+L40+M40+N40 -> 0
B41: PURCHASE OF METHODIST STATIONARY | C41: 160 | D41: 280 | E41: =100+1000 -> 1100 | F41: 70 | I41: =460+40 -> 500 | O41: =C41+D41+E41+F41+G41+H41+I41+J41+K41+L41+M41+N41 -> 2110
B42: DIOCESAN APPEAL | O42: =C42+D42+E42+F42+G42+H42+I42+J42+K42+L42+M42+N42 -> 0
O43: =C43+D43+E43+F43+G43+H43+I43+J43+K43+L43+M43+N43 -> 0
C44: =SUM(C34:C43) -> 160 | D44: =SUM(D34:D43) -> 468 | E44: =SUM(E34:E43) -> 4761 | F44: =SUM(F34:F43) -> 620 | G44: =SUM(G34:G43) -> 5000 | H44: =SUM(H34:H43) -> 3440 | I44: =SUM(I34:I43) -> 500 | J44: =SUM(J34:J43) -> 0 | ... N44: =SUM(N34:N43) -> 7750 | O44: =C44+D44+E44+F44+G44+H44+I44+J44+K44+L44+M44+N44 -> 47235.5
...

Sheet MEMBERS DUES ANALYSIS 17
B1: ASSOCIATION OF METHODIST MENS FELLOWSHIP
B2: KOFORIDUA DIOCESE
B3: WESLEY SOCIETY NSAWAM
B4: MEMBERS DUES CONTRIBUTIONS | C4: 2016 | N4: 2017 | O4: 2017 | R4: 2018 | Z4: 2018
A5: S/N | B5: NAME | C5: OCT | D5: NOV | E5: DEC | F5: JAN | G5: FEB | H5: MAR | I5: APR | J5: MAY | K5: JUNE | L5: JULY | M5: AUG | N5: SEP | O5: OCT | P5: NOV | Q5: DEC | R5: JAN | S5: FEB | T5: MAR | U5: APR | V5: MAY | W5: JUNE | X5: JULY | Y5: AUG | Z5: SEP | AA5: TOTAL | AB5: EXPECTED CONTRIBUTION | AC5: DIFF
C6: GHC | D6: GHC | E6: GHC | F6: GHC | G6: GHC | H6: GHC | I6: GHC | J6: GHC | K6: GHC | L6: GHC | M6: GHC | N6: GHC | O6: GHC | P6: GHC | Q6: GHC | R6: GHC | S6: GHC | T6: GHC | U6: GHC | V6: GHC | W6: GHC | X6: GHC | Y6: GHC | Z6: GHC | AA6: GHC | AB6: GHC | AC6: GHC
A7: 1 | B7: KENNEDY DUODU ACQUAH | C7: 5 | D7: 5 | E7: 5 | F7: 5 | G7: 5 | H7: 5 | I7: 5 | J7: 5 | K7: 5 | L7: 5 | M7: 5 | N7: 5 | O7: 5 | P7: 5 | Q7: 5 | R7: 5 | S7: 5 | T7: 5 | U7: 5 | V7: 5 | W7: 5 | X7: 5 | AA7: =C7+D7+E7+F7+G7+H7+I7+J7+K7+L7+M7+N7+O7+P7+Q7+R7+S7+T7+U7+V7+W7+X7+Y7+Z7 -> 110 | AB7: =5*12 -> 60 | AC7: =AB7-AA7 -> -50
A8: 2 | B8: STEPHEN OBENG ADJEI | C8: 5 | AA8: =C8+D8+E8+F8+G8+H8+I8+J8+K8+L8+M8+N8+O8+P8+Q8+R8+S8+T8+U8+V8+W8+X8+Y8+Z8 -> 5 | AB8: =5*12 -> 60 | AC8: =AB8-AA8 -> 55
A9: 3 | B9: JOSEPH AMIHERE | J9: 5 | K9: 5 | AA9: =C9+D9+E9+F9+G9+H9+I9+J9+K9+L9+M9+N9+O9+P9+Q9+R9+S9+T9+U9+V9+W9+X9+Y9+Z9 -> 10 | AB9: =5*12 -> 60 | AC9: =AB9-AA9 -> 50
A10: 4 | B10: BENJAMIN ATEIMO | C10: 5 | D10: 5 | E10: 5 | F10: 5 | G10: 5 | H10: 5 | I10: 5 | J10: 5 | K10: 5 | L10: 5 | M10: 5 | N10: 5 | O10: 5 | P10: 5 | Q10: 5 | AA10: =C10+D10+E10+F10+G10+H10+I10+J10+K10+L10+M10+N10+O10+P10+Q10+R10+S10+T10+U10+V10+W10+X10+Y10+Z10 -> 75 | AB10: =5*12 -> 60 | AC10: =AB10-AA10 -> -15
A11: 5 | B11: DANIEL ASHEROW | C11: 5 | D11: 5 | E11: 5 | F11: 5 | G11: 5 | H11: 5 | I11: 5 | J11: 5 | K11: 5 | L11: 5 | M11: 5 | AA11: =C11+D11+E11+F11+G11+H11+I11+J11+K11+L11+M11+N11+O11+P11+Q11+R11+S11+T11+U11+V11+W11+X11+Y11+Z11 -> 55 | AB11: =5*12 -> 60 | AC11: =AB11-AA11 -> 5
A12: 6 | B12: ROCKSON-WOOPE THOMAS | C12: 0 | D12: 0 | E12: 0 | F12: 5 | G12: 5 | H12: 5 | I12: 5 | J12: 5 | K12: 5 | L12: 5 | M12: 5 | N12: 5 | O12: 5 | P12: 5 | Q12: 5 | R12: 5 | S12: 5 | T12: 5 | U12: 5 | V12: 5 | AA12: =C12+D12+E12+F12+G12+H12+I12+J12+K12+L12+M12+N12+O12+P12+Q12+R12+S12+T12+U12+V12+W12+X12+Y12+Z12 -> 85 | AB12: =5*9 -> 45 | AC12: =AB12-AA12 -> -40
A13: 7 | B13: ERIC ODURO AMPAABENG | C13: 5 | D13: 5 | E13: 5 | F13: 5 | G13: 5 | H13: 5 | I13: 5 | J13: 5 | K13: 5 | L13: 5 | M13: 5 | N13: 5 | O13: 5 | P13: 5 | Q13: 5 | R13: 5 | S13: 5 | AA13: =C13+D13+E13+F13+G13+H13+I13+J13+K13+L13+M13+N13+O13+P13+Q13+R13+S13+T13+U13+V13+W13+X13+Y13+Z13 -> 85 | AB13: =5*12 -> 60 | AC13: =AB13-AA13 -> -25
A14: 8 | B14: PETER L.Y.N GBORDJOR | C14: 5 | D14: 5 | E14: 5 | F14: 5 | G14: 5 | H14: 5 | I14: 5 | J14: 5 | K14: 5 | L14: 5 | M14: 5 | N14: 5 | O14: 5 | P14: 5 | Q14: 5 | R14: 5 | S14: 5 | T14: 5 | U14: 5 | AA14: =C14+D14+E14+F14+G14+H14+I14+J14+K14+L14+M14+N14+O14+P14+Q14+R14+S14+T14+U14+V14+W14+X14+Y14+Z14 -> 95 | AB14: =5*12 -> 60 | AC14: =AB14-AA14 -> -35
A15: 9 | B15: MICHAEL OKATA | C15: 5 | D15: 5 | E15: 5 | F15: 5 | G15: 5 | H15: 5 | I15: 5 | J15: 5 | K15: 5 | L15: 5 | M15: 5 | N15: 5 | O15: 5 | P15: 5 | Q15: 5 | R15: 5 | S15: 5 | AA15: =C15+D15+E15+F15+G15+H15+I15+J15+K15+L15+M15+N15+O15+P15+Q15+R15+S15+T15+U15+V15+W15+X15+Y15+Z15 -> 85 | AB15: =5*12 -> 60 | AC15: =AB15-AA15 -> -25
A16: 10 | B16: SAMUEL BOSOMPEM | G16: 5 | H16: 5 | I16: 5 | J16: 5 | K16: 5 | L16: 5 | M16: 5 | N16: 5 | O16: 5 | AA16: =C16+D16+E16+F16+G16+H16+I16+J16+K16+L16+M16+N16+O16+P16+Q16+R16+S16+T16+U16+V16+W16+X16+Y16+Z16 -> 45 | AB16: =5*8 -> 40 | AC16: =AB16-AA16 -> -5
A17: 11 | B17: PATRICK NYARKOH | C17: 5 | D17: 5 | E17: 5 | F17: 5 | G17: 5 | H17: 5 | I17: 5 | J17: 5 | K17: 5 | L17: 5 | M17: 5 | N17: 5 | O17: 5 | P17: 5 | Q17: 5 | R17: 5 | AA17: =C17+D17+E17+F17+G17+H17+I17+J17+K17+L17+M17+N17+O17+P17+Q17+R17+S17+T17+U17+V17+W17+X17+Y17+Z17 -> 80 | AB17: =5*12 -> 60 | AC17: =AB17-AA17 -> -20
A18: 12 | B18: DANIEL T NARTEY | C18: 5 | D18: 5 | E18: 5 | F18: 5 | G18: 5 | H18: 5 | I18: 5 | J18: 5 | K18: 5 | L18: 5 | M18: 5 | N18: 5 | O18: 5 | P18: 5 | Q18: 5 | R18: 5 | S18: 5 | T18: 5 | U18: 5 | V18: 5 | W18: 5 | X18: 5 | AA18: =C18+D18+E18+F18+G18+H18+I18+J18+K18+L18+M18+N18+O18+P18+Q18+R18+S18+T18+U18+V18+W18+X18+Y18+Z18 -> 110 | AB18: =5*12 -> 60 | AC18: =AB18-AA18 -> -50
A19: 13 | B19: AGYEMANG BOAKYE | AA19: =C19+D19+E19+F19+G19+H19+I19+J19+K19+L19+M19+N19+O19+P19+Q19+R19+S19+T19+U19+V19+W19+X19+Y19+Z19 -> 0 | AB19: =5*12 -> 60 | AC19: =AB19-AA19 -> 60
A20: 14 | B20: S.D.OWIAFE | C20: 5 | D20: 5 | E20: 5 | F20: 5 | G20: 5 | H20: 5 | I20: 5 | J20: 5 | K20: 5 | L20: 5 | M20: 5 | N20: 5 | O20: 5 | P20: 5 | Q20: 5 | R20: 5 | S20: 5 | AA20: =C20+D20+E20+F20+G20+H20+I20+J20+K20+L20+M20+N20+O20+P20+Q20+R20+S20+T20+U20+V20+W20+X20+Y20+Z20 -> 85 | AB20: =5*12 -> 60 | AC20: =AB20-AA20 -> -25
A21: 15 | B21: SAMUEL NICHOLAS OSEI | AA21: =C21+D21+E21+F21+G21+H21+I21+J21+K21+L21+M21+N21+O21+P21+Q21+R21+S21+T21+U21+V21+W21+X21+Y21+Z21 -> 0 | AB21: =5*12 -> 60 | AC21: =AB21-AA21 -> 60
A22: 16 | B22: PRINCE HENRY AIDOO | C22: 5 | D22: 5 | E22: 5 | F22: 5 | G22: 5 | H22: 5 | I22: 5 | J22: 5 | K22: 5 | L22: 5 | M22: 5 | N22: 5 | O22: 5 | P22: 5 | Q22: 5 | AA22: =C22+D22+E22+F22+G22+H22+I22+J22+K22+L22+M22+N22+O22+P22+Q22+R22+S22+T22+U22+V22+W22+X22+Y22+Z22 -> 75 | AB22: =5*12 -> 60 | AC22: =AB22-AA22 -> -15
A23: 17 | B23: VINCENT ADAMS | C23: 5 | D23: 5 | E23: 5 | F23: 5 | G23: 5 | H23: 5 | I23: 5 | J23: 5 | K23: 5 | L23: 5 | M23: 5 | N23: 5 | O23: 5 | P23: 5 | AA23: =C23+D23+E23+F23+G23+H23+I23+J23+K23+L23+M23+N23+O23+P23+Q23+R23+S23+T23+U23+V23+W23+X23+Y23+Z23 -> 70 | AB23: =5*12 -> 60 | AC23: =AB23-AA23 -> -10
A24: 18 | B24: STEPHEN ODURO | AA24: =C24+D24+E24+F24+G24+H24+I24+J24+K24+L24+M24+N24+O24+P24+Q24+R24+S24+T24+U24+V24+W24+X24+Y24+Z24 -> 0 | AB24: =5*12 -> 60 | AC24: =AB24-AA24 -> 60
A25: 19 | B25: E.J. ARYEETEY | AA25: =C25+D25+E25+F25+G25+H25+I25+J25+K25+L25+M25+N25+O25+P25+Q25+R25+S25+T25+U25+V25+W25+X25+Y25+Z25 -> 0 | AB25: =5*12 -> 60 | AC25: =AB25-AA25 -> 60
A26: 20 | B26: ALEX WILLIAMS | C26: 5 | D26: 5 | E26: 5 | F26: 5 | G26: 5 | H26: 5 | I26: 5 | AA26: =C26+D26+E26+F26+G26+H26+I26+J26+K26+L26+M26+N26+O26+P26+Q26+R26+S26+T26+U26+V26+W26+X26+Y26+Z26 -> 35 | AB26: =5*12 -> 60 | AC26: =AB26-AA26 -> 25
A27: 21 | B27: J.B ESHUN | AA27: =C27+D27+E27+F27+G27+H27+I27+J27+K27+L27+M27+N27+O27+P27+Q27+R27+S27+T27+U27+V27+W27+X27+Y27+Z27 -> 0 | AB27: =5*12 -> 60 | AC27: =AB27-AA27 -> 60
A28: 22 | B28: NANA KWAKYE ABROKWA | AA28: =C28+D28+E28+F28+G28+H28+I28+J28+K28+L28+M28+N28+O28+P28+Q28+R28+S28+T28+U28+V28+W28+X28+Y28+Z28 -> 0 | AB28: =5*12 -> 60 | AC28: =AB28-AA28 -> 60
A29: 23 | B29: EMMANUEL MANTEY | AA29: =C29+D29+E29+F29+G29+H29+I29+J29+K29+L29+M29+N29+O29+P29+Q29+R29+S29+T29+U29+V29+W29+X29+Y29+Z29 -> 0 | AB29: =5*12 -> 60 | AC29: =AB29-AA29 -> 60
A30: 24 | B30: EMMANUEL AMANKWAH | C30: 5 | D30: 5 | E30: 5 | F30: 5 | G30: 5 | H30: 5 | I30: 5 | J30: 5 | K30: 5 | L30: 5 | M30: 5 | N30: 5 | O30: 5 | P30: 5 | AA30: =C30+D30+E30+F30+G30+H30+I30+J30+K30+L30+M30+N30+O30+P30+Q30+R30+S30+T30+U30+V30+W30+X30+Y30+Z30 -> 70 | AB30: =5*12 -> 60 | AC30: =AB30-AA30 -> -10
A31: 25 | B31: ENOCH SARQUAH | C31: 5 | D31: 5 | E31: 5 | F31: 5 | G31: 5 | H31: 5 | I31: 5 | J31: 5 | K31: 5 | L31: 5 | M31: 5 | N31: 5 | O31: 5 | P31: 5 | Q31: 5 | R31: 5 | AA31: =C31+D31+E31+F31+G31+H31+I31+J31+K31+L31+M31+N31+O31+P31+Q31+R31+S31+T31+U31+V31+W31+X31+Y31+Z31 -> 80 | AB31: =5*12 -> 60 | AC31: =AB31-AA31 -> -20
A32: 26 | B32: GILBERT JERRY AMOAH | C32: 5 | D32: 5 | E32: 5 | F32: 5 | G32: 5 | H32: 5 | I32: 5 | J32: 5 | K32: 5 | L32: 5 | M32: 5 | N32: 5 | AA32: =C32+D32+E32+F32+G32+H32+I32+J32+K32+L32+M32+N32+O32+P32+Q32+R32+S32+T32+U32+V32+W32+X32+Y32+Z32 -> 60 | AB32: =5*12 -> 60 | AC32: =AB32-AA32 -> 0
A33: 27 | B33: EMMANUEL AMHED OSAFO | C33: 5 | D33: 5 | E33: 5 | F33: 5 | G33: 5 | H33: 5 | I33: 5 | J33: 5 | K33: 5 | L33: 5 | M33: 5 | N33: 5 | O33: 5 | AA33: =C33+D33+E33+F33+G33+H33+I33+J33+K33+L33+M33+N33+O33+P33+Q33+R33+S33+T33+U33+V33+W33+X33+Y33+Z33 -> 65 | AB33: =5*12 -> 60 | AC33: =AB33-AA33 -> -5
A34: 28 | B34: JOSHUA TETTEY DAWUTEY | F34: 5 | G34: 5 | H34: 5 | I34: 5 | J34: 5 | K34: 5 | L34: 5 | M34: 5 | N34: 5 | O34: 5 | P34: 5 | Q34: 5 | R34: 5 | S34: 5 | T34: 5 | U34: 5 | V34: 5 | W34: 5 | AA34: =C34+D34+E34+F34+G34+H34+I34+J34+K34+L34+M34+N34+O34+P34+Q34+R34+S34+T34+U34+V34+W34+X34+Y34+Z34 -> 90 | AB34: =5*12 -> 60 | AC34: =AB34-AA34 -> -30
A35: 29 | B35: KWESI PREMPEH | AA35: =C35+D35+E35+F35+G35+H35+I35+J35+K35+L35+M35+N35+O35+P35+Q35+R35+S35+T35+U35+V35+W35+X35+Y35+Z35 -> 0 | AB35: =5*12 -> 60 | AC35: =AB35-AA35 -> 60
A36: 30 | B36: ROBERT OFOSU AGYEMANG | C36: 5 | D36: 5 | E36: 5 | F36: 5 | G36: 5 | H36: 5 | I36: 5 | J36: 5 | K36: 5 | L36: 5 | M36: 5 | AA36: =C36+D36+E36+F36+G36+H36+I36+J36+K36+L36+M36+N36+O36+P36+Q36+R36+S36+T36+U36+V36+W36+X36+Y36+Z36 -> 55 | AB36: =5*12 -> 60 | AC36: =AB36-AA36 -> 5
A37: 31 | B37: OSCAR DAPAAH | AA37: =C37+D37+E37+F37+G37+H37+I37+J37+K37+L37+M37+N37+O37+P37+Q37+R37+S37+T37+U37+V37+W37+X37+Y37+Z37 -> 0 | AB37: =5*12 -> 60 | AC37: =AB37-AA37 -> 60
A38: 32 | B38: ANDREWS ADUFUL | C38: 5 | D38: 5 | E38: 5 | F38: 5 | G38: 5 | H38: 5 | I38: 5 | J38: 5 | K38: 5 | L38: 5 | M38: 5 | N38: 5 | O38: 5 | P38: 5 | Q38: 5 | R38: 5 | S38: 5 | T38: 5 | U38: 5 | V38: 5 | AA38: =C38+D38+E38+F38+G38+H38+I38+J38+K38+L38+M38+N38+O38+P38+Q38+R38+S38+T38+U38+V38+W38+X38+Y38+Z38 -> 100 | AB38: =5*12 -> 60 | AC38: =AB38-AA38 -> -40
A39: 33 | B39: SYDNEY SIAW WILLIAMS | R39: 5 | S39: 5 | AA39: =C39+D39+E39+F39+G39+H39+I39+J39+K39+L39+M39+N39+O39+P39+Q39+R39+S39+T39+U39+V39+W39+X39+Y39+Z39 -> 10 | AB39: =5*12 -> 60 | AC39: =AB39-AA39 -> 50
A40: 34 | B40: K.A BEDIAKO | C40: 5 | D40: 5 | E40: 5 | F40: 5 | G40: 5 | H40: 5 | I40: 5 | J40: 5 | K40: 5 | L40: 5 | M40: 5 | N40: 5 | AA40: =C40+D40+E40+F40+G40+H40+I40+J40+K40+L40+M40+N40+O40+P40+Q40+R40+S40+T40+U40+V40+W40+X40+Y40+Z40 -> 60 | AB40: =5*12 -> 60 | AC40: =AB40-AA40 -> 0
...

Sheet TITHE
A1: =+Expend!A1 -> THE METHODIST CHURCH GHANA
A2: =+Expend!A2 -> ACCRA NORTH DIOCESE
A3: =+Expend!A3 -> GA SUB-URBAN CIRCUIT
A4: =+Expend!A4 -> HEBRON SOCIETY
A5: =+Expend!A5 -> STATEMENT OF ACCOUNT FOR THE PERIOD 1ST JANUARY,2024 TO 31ST DECEMBER,2024
B6: TITHE | C6: 2023 | D6: 2023 | E6: 2023 | F6: 2023 | G6: 2023 | H6: 2023 | I6: 2023 | J6: 2023 | K6: 2024 | L6: 2024 | M6: 2024 | N6: 2024 | O6: 2024 | P6: 2024 | Q6: 2024 | R6: 2024 | S6: 2024 | T6: 2024 | U6: 2024 | V6: 2024 | W6: 2024 | X6: 2024 | Y6: 2024 | Z6: 2024
A7: S/N | B7: NAME | C7: MAY | D7: JUN | E7: JUL | F7: AUG | G7: SEP | H7: OCT | I7: NOV | J7: DEC | K7: JAN | L7: FEB | M7: MAR | N7: APR | O7: MAY | P7: JUN | Q7: JUL | R7: AUG | S7: SEP | T7: OCT | U7: NOV | V7: DEC | W7: JAN | X7: FEB | Y7: MAR | Z7: APR | AA7: TOTAL
C8: GHC | D8: GHC | E8: GHC | F8: GHC | G8: GHC | H8: GHC | I8: GHC | J8: GHC | K8: GHC | L8: GHC | M8: GHC | N8: GHC | O8: GHC | P8: GHC | Q8: GHC | R8: GHC | S8: GHC | T8: GHC | U8: GHC | V8: GHC | W8: GHC | X8: GHC | Y8: GHC | Z8: GHC | AA8: GHC
A9: 1 | B9: GOLDA KAMMASSAH | K9: 50 | L9: 50 | M9: 50 | N9: 50 | O9: 50 | P9: 50 | Q9: 50 | R9: 50 | S9: 50 | T9: 50 | U9: 50 | AA9: =SUM(C9:Z9) -> 550
A10: 2 | B10: ERICA DONKOR | K10: 150 | L10: 60 | M10: 60 | N10: 100 | O10: 100 | P10: 100 | Q10: 100 | R10: 100 | S10: 100 | T10: 100 | U10: 100 | V10: 120 | AA10: =SUM(C10:Z10) -> 1190
A11: 3 | B11: CHARLES FRIMPONG | K11: 150 | L11: 150 | M11: 150 | N11: 150 | O11: 150 | P11: 150 | Q11: 150 | R11: 150 | S11: 150 | T11: 150 | U11: 100 | AA11: =SUM(C11:Z11) -> 1600
A12: 4 | B12: EMMANUEL ASADU | K12: 500 | L12: 500 | M12: 500 | N12: 500 | O12: 500 | P12: 500 | Q12: 500 | R12: 600 | S12: 500 | T12: 500 | U12: 500 | AA12: =SUM(C12:Z12) -> 5600
A13: 5 | B13: JOANA WADDIE | K13: 60 | L13: 60 | M13: 60 | N13: 60 | O13: 60 | P13: 60 | Q13: 60 | R13: 60 | S13: 60 | T13: 70 | U13: 60 | V13: 60 | AA13: =SUM(C13:Z13) -> 730
A14: 6 | B14: DORIS MARFO | K14: 250 | L14: 220 | M14: 230 | N14: 250 | O14: 240 | P14: 250 | Q14: 250 | R14: 250 | S14: 250 | T14: 250 | U14: 250 | AA14: =SUM(C14:Z14) -> 2690
A15: 7 | B15: GLORIA ASARE | K15: 200 | L15: 1100 | M15: 1600 | N15: 1100 | O15: 1100 | P15: 1100 | Q15: 1100 | R15: 1100 | S15: 1100 | T15: 1100 | U15: 1100 | AA15: =SUM(C15:Z15) -> 11700
A16: 8 | B16: PATRICK NYARKOH | K16: 1600 | L16: 1600 | M16: 1600 | N16: 1600 | O16: 1600 | P16: 1600 | Q16: 1600 | R16: 1600 | S16: 1600 | T16: 1600 | U16: 1850 | AA16: =SUM(C16:Z16) -> 17850
A17: 9 | B17: DORIS NYARKOH | K17: 660 | L17: 660 | M17: 660 | N17: 660 | O17: 660 | P17: 660 | Q17: 660 | R17: 660 | S17: 800 | T17: 800 | U17: 800 | AA17: =SUM(C17:Z17) -> 7680
A18: 10 | B18: JUSTINA DADZIE | K18: 100 | L18: 100 | M18: 100 | N18: 100 | O18: 100 | P18: 100 | Q18: 100 | R18: 100 | S18: 100 | T18: 100 | U18: 100 | AA18: =SUM(C18:Z18) -> 1100
A19: 11 | B19: MACHELLE YAMOAH | K19: 265 | L19: 265 | M19: 265 | N19: 265 | O19: 535 | P19: 265 | Q19: 670 | R19: 400 | S19: 400 | T19: 400 | U19: 400 | V19: 400 | AA19: =SUM(C19:Z19) -> 4530
A20: 12 | B20: EDWARD QUARNOR | K20: 170 | L20: 200 | M20: 160 | N20: 150 | O20: 160 | P20: 180 | Q20: 150 | R20: 100 | S20: 130 | T20: 200 | U20: 150 | AA20: =SUM(C20:Z20) -> 1750
A21: 13 | B21: SETH ASARE | K21: 60 | L21: 60 | M21: 60 | N21: 60 | O21: 60 | P21: 60 | Q21: 60 | R21: 60 | S21: 60 | T21: 60 | U21: 60 | AA21: =SUM(C21:Z21) -> 660
A22: 14 | B22: JULIANA ASADU | K22: 350 | L22: 350 | M22: 350 | N22: 350 | O22: 353 | P22: 353 | Q22: 350 | R22: 350 | S22: 400 | T22: 370 | U22: 350 | V22: 355 | AA22: =SUM(C22:Z22) -> 4281
A23: 15 | B23: PHYLLIS NYARKO | K23: 50 | L23: 70 | M23: =60+100+50 -> 210 | N23: 100 | O23: 50 | P23: 100 | Q23: 50 | R23: 100 | S23: 100 | T23: 100 | AA23: =SUM(C23:Z23) -> 930
A24: 16 | B24: JEMIMA AFRIYIE ASAMOAH | K24: 100 | L24: 100 | M24: 100 | N24: 100 | O24: 100 | P24: 100 | Q24: 100 | R24: 100 | S24: 100 | T24: 300 | U24: 300 | AA24: =SUM(C24:Z24) -> 1500
A25: 17 | B25: PHILIP OPOKU | G25: 100 | H25: 100 | I25: 100 | J25: 100 | K25: 100 | L25: 100 | M25: 100 | AA25: =SUM(C25:Z25) -> 700
A26: 18 | B26: FELIX YAMOAH | E26: 100 | F26: 100 | G26: 100 | H26: 100 | I26: 100 | J26: 100 | K26: 150 | L26: 150 | M26: 150 | N26: 150 | O26: 150 | P26: 150 | Q26: 150 | R26: 150 | AA26: =SUM(C26:Z26) -> 1800
A27: 19 | B27: PETER ASARE | J27: 400 | K27: 400 | L27: 400 | M27: 400 | N27: 400 | O27: 400 | P27: 400 | Q27: 400 | R27: 400 | S27: 400 | T27: 400 | U27: 400 | AA27: =SUM(C27:Z27) -> 4800
A28: 20 | B28: ASANTEWA MARINA | J28: 50 | K28: 20 | L28: 50 | M28: 40 | N28: 50 | O28: 50 | P28: 50 | Q28: 50 | R28: 50 | S28: 50 | T28: 50 | U28: 50 | V28: 100 | AA28: =SUM(C28:Z28) -> 660
A29: 21 | B29: NO NAME | K29: 55 | P29: 0 | AA29: =SUM(C29:Z29) -> 55
A30: 22 | B30: PHILOMINA AGYEKUM | K30: 20 | AA30: =SUM(C30:Z30) -> 20
A31: 23 | B31: AMA TUTUA | K31: 1505 | L31: 1520 | M31: 1520 | N31: 1520 | O31: 1600 | P31: 1700 | Q31: 1000 | R31: 1750 | S31: 1800 | AA31: =SUM(C31:Z31) -> 13915
A32: 24 | B32: SAMILIA ASANTE | K32: 30 | AA32: =SUM(C32:Z32) -> 30
A33: 25 | B33: SAMUEL ASARE | K33: 150 | L33: 150 | M33: 150 | N33: 150 | O33: 350 | P33: 180 | Q33: 180 | R33: 360 | S33: 360 | T33: 360 | U33: 360 | AA33: =SUM(C33:Z33) -> 2750
A34: 26 | B34: OBODIA ADJA | AA34: =SUM(C34:Z34) -> 0
A35: 27 | B35: ESTHER ASARE | J35: 10 | K35: 10 | L35: 20 | M35: 20 | N35: 20 | O35: 20 | P35: 20 | Q35: 20 | R35: 20 | S35: 20 | T35: 20 | U35: 20 | V35: 20 | AA35: =SUM(C35:Z35) -> 240
A36: 28 | B36: KATE ANKRAH | K36: 40 | L36: 40 | M36: 40 | N36: 40 | O36: 40 | P36: 40 | Q36: 40 | R36: 40 | S36: 40 | T36: 40 | U36: 40 | V36: 40 | AA36: =SUM(C36:Z36) -> 480
A37: 29 | B37: COMFORT BENABE | K37: 60 | AA37: =SUM(C37:Z37) -> 60
A38: 30 | B38: UNKNOWN | AA38: =SUM(C38:Z38) -> 0
A39: 31 | B39: VICTORIA OPOKU | H39: 20 | I39: 20 | J39: 20 | K39: 20 | L39: 20 | M39: 20 | N39: 20 | O39: 20 | P39: 20 | Q39: 20 | R39: 20 | S39: 20 | AA39: =SUM(C39:Z39) -> 240
A40: 32 | B40: ALFRED OKYERE | H40: 100 | I40: 100 | J40: 100 | K40: 100 | AA40: =SUM(C40:Z40) -> 400
...

Sheet CASH BOOK
A1: =+TITHE!A1:N1 -> THE METHODIST CHURCH GHANA
A2: =+TITHE!A2:N2 -> ACCRA NORTH DIOCESE
A3: =+TITHE!A3:N3 -> GA SUB-URBAN CIRCUIT
A4: =+TITHE!A4:N4 -> HEBRON SOCIETY
A5: CASHBOOK
A6: RECEIPTS | H6: PAYMENTS
A7: DATE | B7: DETAILS | C7: FOLIO | D7: REPUBLIC | E7: GA RURAL | F7: CASH | H7: DATE | I7: DETAILS | J7: FOLIO | K7: REPUBLIC | L7: GA RURAL | M7: CASH
D8: GHC | E8: GHC | F8: GHC | K8: GHC | L8: GHC | M8: GHC
A9: 44470 | B9: Bal B/F | D9: =+'Rec & Pmt'!C76 -> 200 | E9: =+'Rec & Pmt'!C75 -> 52205.88 | F9: =+'Rec & Pmt'!C77 -> 6557.7 | H9: 44470 | I9: Bal B/F
B10: JANUARY | E10: =7212.6+1000 -> 8212.6 | F10: ='weekly income statement'!C68 -> 6134.8 | I10: JANUARY | L10: =+Expend!C84+231.2 -> 60231.2 | M10: =Expend!C108-231.2 -> 9547
B11: FEBRUARY | E11: =1600+9635+5360+7387 -> 23982 | F11: ='weekly income statement'!D68 -> 24320.2 | I11: FEBRUARY | L11: =+Expend!D84 -> 46000 | M11: =Expend!D108-L11 -> 25450
B12: MARCH | E12: =22600+9000+5000 -> 36600 | F12: ='weekly income statement'!E68 -> 63348.9 | I12: MARCH | L12: =+Expend!E84-4000-3000-4000 -> 14000 | M12: =Expend!E108-L12 -> 55791
B13: APRIL | E13: 26065 | F13: ='weekly income statement'!F68 -> 26461.6 | I13: APRIL | L13: =+Expend!G89-Expend!G84+25000+1600 -> 26600 | M13: =Expend!F108-L13 -> 28885
B14: MAY | F14: ='weekly income statement'!G68 -> 17574.3 | I14: MAY | M14: =Expend!G108-L14 -> 7750
B15: JUNE | E15: =12360+34890 -> 47250 | F15: ='weekly income statement'!H68 -> 54094.5 | I15: JUNE | L15: =+Expend!H84+1000 -> 44040 | M15: =Expend!H108-L15 -> 54290
B16: JULY | E16: =1600+2610+17000 -> 21210 | F16: ='weekly income statement'!I68 -> 14344.8 | I16: JULY | L16: =+Expend!I84 -> 20000 | M16: =Expend!I108-L16 -> 24210
B17: AUGUST | E17: 1500 | F17: ='weekly income statement'!J68 -> 7404.5 | I17: AUGUST | L17: =+Expend!J84 -> 0 | M17: =Expend!J108-L17 -> 2900
B18: SEPTEMBER | E18: 39720 | F18: ='weekly income statement'!K68 -> 44106.6 | I18: SEPTEMBER | M18: =Expend!K108 -> 42220
B19: OCTOBER | E19: 18000 | F19: ='weekly income statement'!L68 -> 13859.3 | I19: OCTOBER | L19: =+Expend!L80-6000 -> 40000 | M19: =Expend!L108-L19 -> 25100
B20: NOVEMBER | E20: 14000 | F20: ='weekly income statement'!M68 -> 50169.4 | I20: NOVEMBER | M20: =Expend!M108 -> 48536.5
B21: DECEMBER | E21: =34880+14505+3890 -> 53275 | F21: ='weekly income statement'!N68 -> 75147.7 | I21: DECEMBER | L21: =20000+8254.49+8241.29+38460+2020 -> 76975.78 | M21: =Expend!N108-L21 -> 72505
D25: =SUM(D9:D24) -> 200 | E25: =SUM(E9:E24) -> 342020.48 | F25: =SUM(F9:F24) -> 403524.3 | K25: =SUM(K9:K24) -> 0 | L25: =SUM(L9:L24) -> 327846.98 | M25: =SUM(M9:M24) -> 397184.5
H26: CLOSING BALANCE | K26: =D25-K25 -> 200 | L26: =E25-L25 -> 14173.5 | M26: =F25-M25 -> 6339.8
K28: 200 | M28: =K28*L28 -> 0
K29: 100 | M29: =K29*L29 -> 0
K30: 50 | M30: =K30*L30 -> 0
K31: 20 | M31: =K31*L31 -> 0
K32: 10 | M32: =K32*L32 -> 0
K33: 5 | M33: =K33*L33 -> 0
K34: 2 | M34: =K34*L34 -> 0
K35: 1 | M35: =K35*L35 -> 0
M36: =SUM(M28:M35) -> 0
M37: =12160+7802 -> 19962
M38: =+M36-M37 -> -19962
M39: =SUM(M37:M38) -> 0
L41: 50000
L42: -25000
L43: -1640
L44: =SUM(L41:L43) -> 23360
L45: -3080

Sheet ASSETS
A1: TRINITY METHODIST CHURCH
A2: FIXED ASSETS REGISTER
A3: S/N | B3: DATE | C3: DETAILS | D3: QTY | E3: VALUE | F3: REMARKS
A4: 1 | C4: PLASTIC CHAIRS | D4: 20 | E4: 540 | F4: CHURCH
A5: 2 | C5: PLASTIC CHAIRS | D5: 20 | E5: 540 | F5: CHURCH
A6: 3 | C6: KONKA | D6: 1 | E6: 550 | F6: CHURCH
A7: 4 | C7: SPEAKER | D7: 1 | E7: 1200 | F7: CHURCH
A8: 5 | C8: CORDLESS MIC | D8: 2 | F8: DONATED
A9: 6 | C9: PULPIT | D9: 1 | E9: 500 | F9: CHURCH
A10: 7 | C10: LAND | D10: 2PLOTS | E10: 46450 | F10: CHURCH
A11: 8 | C11: FILLING | E11: 35740 | F11: CHURCH
A12: 9 | C12: CANOPY | D12: 1 | E12: 2500 | F12: DONATED
A13: 10 | C13: PLASTIC CHAIRS | D13: 42 | F13: DONATED
A14: 11 | C14: TAMBOURINES | D14: 2 | F14: DONATED
A15: 12 | C15: SPEAKER | D15: 1 | F15: DONATED
A16: 13 | C16: CORDED MIC | D16: 1 | F16: DONATED
A17: 14 | C17: TABLE | D17: 1 | F17: DONATED
A18: 15 | C18: OFFERING BOWL | D18: 1 | F18: DONATED
A19: 16 | C19: KEYBOARD | D19: 1 | E19: 5000 | F19: DONATED
C20: INDUSTRIAL FANS | D20: 2 | E20: 3000
C21: STANDING FAN | D21: 1 | E21: 550
C22: DRUMSET | D22: 1 | E22: 3600
C23: MICRO PHONES | D23: 3 | F23: DONATED
C24: CHAIRS | D24: 40 | E24: 3440

Sheet RETURNS FOR CIRCUIT
A1: THE METHODIST CHURCH GHANA
A2: NORTHERN ACCRA DIOCESE
A3: GA-SUB URBAN CIRCUIT
A4: HEBRON SOCIETY
A6: SOCIETY REVENUE ANALYSIS SHEET | C6: SOCIETY CODE | F6: MONTH | G6: JANUARY
A7: DATE : | F7: WEEK
A9: INCOME SOURCE | B9: NORMAL SERVICE | C9: WEEKDAY | D9: TOTAL | E9: CONNEX | F9: DIOCESE | G9: CIRCUIT | H9: TOTAL ASSESSMENT | I9: SOCIETY
E10: 0.4 | F10: 0.09 | G10: 0.13 | I10: 0.38
B11: GHS | C11: GHS | D11: GHS | E11: GHS | F11: GHS | G11: GHS | H11: GHS | I11: GHS
A12: TITHE | B12: ='RECEIPTS AND PAYMENT ANANLYSIS'!B9 -> 2085 | C12: ='RECEIPTS AND PAYMENT ANANLYSIS'!B10 -> 482.6 | D12: =SUM(B12:C12) -> 2567.6 | E12: =D12*$E$10 -> 1027.04 | F12: =D12*$F$10 -> 231.084 | G12: =D12*$G$10 -> 333.788 | H12: =SUM(E12:G12) -> 1591.912 | I12: =D12*$I$10 -> 975.688
A13: OFFERING | B13: ='RECEIPTS AND PAYMENT ANANLYSIS'!B8 -> 2682.2 | D13: =SUM(B13:C13) -> 2682.2 | E13: =D13*$E$10 -> 1072.88 | F13: =D13*$F$10 -> 241.398 | G13: =D13*$G$10 -> 348.686 | H13: =SUM(E13:G13) -> 1662.964 | I13: =D13*$I$10 -> 1019.236
A14: KOFI & AMA | D14: =SUM(B14:C14) -> 0 | E14: =D14*$E$10 -> 0 | F14: =D14*$F$10 -> 0 | G14: =D14*$G$10 -> 0 | H14: =SUM(E14:G14) -> 0 | I14: =D14*$I$10 -> 0
A15: THANKSOFFERING | B15: ='RECEIPTS AND PAYMENT ANANLYSIS'!B11 -> 350 | D15: =SUM(B15:C15) -> 350 | E15: =D15*$E$10 -> 140 | F15: =D15*$F$10 -> 31.5 | G15: =D15*$G$10 -> 45.5 | H15: =SUM(E15:G15) -> 217 | I15: =D15*$I$10 -> 133
A16: SO MU BI | D16: =SUM(B16:C16) -> 0 | E16: =D16*$E$10 -> 0 | F16: =D16*$F$10 -> 0 | G16: =D16*$G$10 -> 0 | H16: =SUM(E16:G16) -> 0 | I16: =D16*$I$10 -> 0
A17: SPECIAL OFFERING | B17: ='RECEIPTS AND PAYMENT ANANLYSIS'!B14 -> 0 | D17: =SUM(B17:C17) -> 0 | E17: =D17*$E$10 -> 0 | F17: =D17*$F$10 -> 0 | G17: =D17*$G$10 -> 0 | H17: =SUM(E17:G17) -> 0 | I17: =D17*$I$10 -> 0
A18: GRANDTOTAL | B18: =SUM(B12:B17) -> 5117.2 | C18: =SUM(C12:C17) -> 482.6 | D18: =SUM(D12:D17) -> 5599.8 | E18: =SUM(E12:E17) -> 2239.92 | F18: =SUM(F12:F17) -> 503.982 | G18: =SUM(G12:G17) -> 727.974 | H18: =SUM(H12:H17) -> 3471.876 | I18: =SUM(I12:I17) -> 2127.924
A21: THE METHODIST CHURCH GHANA
A22: NORTHERN ACCRA DIOCESE
A23: GA-SUB URBAN CIRCUIT
A24: HEBRON SOCIETY
A26: SOCIETY REVENUE ANALYSIS SHEET | C26: SOCIETY CODE | F26: MONTH | G26: FEBRUARY
A27: DATE : | F27: WEEK
A29: INCOME SOURCE | B29: NORMAL SERVICE | C29: WEEKDAY | D29: TOTAL | E29: CONNEX | F29: DIOCESE | G29: CIRCUIT | H29: TOTAL ASSESSMENT | I29: SOCIETY
E30: 0.4 | F30: 0.09 | G30: 0.13 | I30: 0.38
B31: GHS | C31: GHS | D31: GHS | E31: GHS | F31: GHS | G31: GHS | H31: GHS | I31: GHS
A32: TITHE | B32: ='RECEIPTS AND PAYMENT ANANLYSIS'!C9 -> 9010 | C32: ='RECEIPTS AND PAYMENT ANANLYSIS'!C10 -> 260 | D32: =SUM(B32:C32) -> 9270 | E32: =D32*$E$10 -> 3708 | F32: =D32*$F$10 -> 834.3 | G32: =D32*$G$10 -> 1205.1 | H32: =SUM(E32:G32) -> 5747.4 | I32: =D32*$I$10 -> 3522.6
A33: OFFERING | B33: ='RECEIPTS AND PAYMENT ANANLYSIS'!C8 -> 2715.3 | D33: =SUM(B33:C33) -> 2715.3 | E33: =D33*$E$10 -> 1086.12 | F33: =D33*$F$10 -> 244.377 | G33: =D33*$G$10 -> 352.989 | H33: =SUM(E33:G33) -> 1683.486 | I33: =D33*$I$10 -> 1031.814
A34: KOFI & AMA | D34: =SUM(B34:C34) -> 0 | E34: =D34*$E$10 -> 0 | F34: =D34*$F$10 -> 0 | G34: =D34*$G$10 -> 0 | H34: =SUM(E34:G34) -> 0 | I34: =D34*$I$10 -> 0
A35: THANKSOFFERING | B35: ='RECEIPTS AND PAYMENT ANANLYSIS'!C11 -> 200 | D35: =SUM(B35:C35) -> 200 | E35: =D35*$E$10 -> 80 | F35: =D35*$F$10 -> 18 | G35: =D35*$G$10 -> 26 | H35: =SUM(E35:G35) -> 124 | I35: =D35*$I$10 -> 76
A36: SO MU BI | D36: =SUM(B36:C36) -> 0 | E36: =D36*$E$10 -> 0 | F36: =D36*$F$10 -> 0 | G36: =D36*$G$10 -> 0 | H36: =SUM(E36:G36) -> 0 | I36: =D36*$I$10 -> 0
A37: SPECIAL OFFERING | B37: ='RECEIPTS AND PAYMENT ANANLYSIS'!C14 -> 0 | D37: =SUM(B37:C37) -> 0 | E37: =D37*$E$10 -> 0 | F37: =D37*$F$10 -> 0 | G37: =D37*$G$10 -> 0 | H37: =SUM(E37:G37) -> 0 | I37: =D37*$I$10 -> 0
A38: GRANDTOTAL | B38: =SUM(B32:B37) -> 11925.3 | C38: =SUM(C32:C37) -> 260 | D38: =SUM(D32:D37) -> 12185.3 | E38: =SUM(E32:E37) -> 4874.12 | F38: =SUM(F32:F37) -> 1096.677 | G38: =SUM(G32:G37) -> 1584.089 | H38: =SUM(H32:H37) -> 7554.886 | I38: =SUM(I32:I37) -> 4630.414
A41: THE METHODIST CHURCH GHANA
A42: NORTHERN ACCRA DIOCESE
A43: GA-SUB URBAN CIRCUIT
A44: HEBRON SOCIETY
A46: SOCIETY REVENUE ANALYSIS SHEET | C46: SOCIETY CODE | F46: MONTH | G46: MARCH
A47: DATE : | F47: WEEK
A49: INCOME SOURCE | B49: NORMAL SERVICE | C49: WEEKDAY | D49: TOTAL | E49: CONNEX | F49: DIOCESE | G49: CIRCUIT | H49: TOTAL ASSESSMENT | I49: SOCIETY
E50: 0.4 | F50: 0.09 | G50: 0.13 | I50: 0.38
...

Sheet Stage
A1: PROJECT ACCOUNT | G1: HEBRON METHODIST CHURCH
A2: FOUNDATION COST | D2: 155306 | G2: ESTIMATE OF WORK TO BE DONE TO COMPLETE STAGE 1
A3: ADVAVCE PAYMENT TO CONTRACTOR | B3: FIRST PAYMENT | C3: 40356 | H3: QTY | I3: RATE | J3: AMOUNT
B4: SECOND PAYMENT | C4: 40000 | I4: GHS | J4: GHS
B5: THIRD PAYMENT | C5: 22500 | G5: CEMENT | H5: 150 | I5: 90 | J5: =+H5*I5 -> 13500
B6: TOTAL CHEQUES ISSUED | C6: =SUM(C3:C5) -> 102856 | G6: SAND | H6: 1 | I6: 2000 | J6: =+H6*I6 -> 2000 | K6: 1400
B7: 15 TRIPS OF SAND | C7: -7500 | D7: contactor through advance from church | G7: STONE | H7: 2 | I7: 2600 | J7: =+H7*I7 -> 5200 | K7: 2400
C8: =SUM(C6:C7) -> 95356 | G8: CONCRETE WORKS | H8: 1 | I8: 4800 | J8: =+H8*I8 -> 4800
B9: 10 Additional Trips of Sand@700 | C9: -7000 | D9: church | E9: variation | G9: RUBBER (DPM) | H9: 5 | I9: 600 | J9: =+H9*I9 -> 3000
B10: 1 TRIP BIG SAND | C10: -1000 | D10: church | E10: variation | G10: WATER | H10: 2 | I10: 200 | J10: =+H10*I10 -> 400
B11: Payloader for the road sand | C11: -500 | D11: church | E11: variation | G11: CONCRETE MIXER RENTAL | H11: 2 | I11: 500 | J11: =+H11*I11 -> 1000
B12: 100 BAGS OF CEMENT DONATION | C12: -9000 | D12: church | G12: BACKHOLE RENTAL | H12: 1 | I12: 1500 | J12: =+H12*I12 -> 1500
J13: =SUM(J5:J12) -> 31400
